Exception on /views/results [POST]
Traceback (most recent call last):
  File "/home/aryton/Kode/counter_point/venv/lib/python3.6/site-packages/flask/app.py", line 2292, in wsgi_app
    response = self.full_dispatch_request()
  File "/home/aryton/Kode/counter_point/venv/lib/python3.6/site-packages/flask/app.py", line 1815, in full_dispatch_request
    rv = self.handle_user_exception(e)
  File "/home/aryton/Kode/counter_point/venv/lib/python3.6/site-packages/flask_restplus/api.py", line 583, in error_router
    return original_handler(e)
  File "/home/aryton/Kode/counter_point/venv/lib/python3.6/site-packages/flask/app.py", line 1718, in handle_user_exception
    reraise(exc_type, exc_value, tb)
  File "/home/aryton/Kode/counter_point/venv/lib/python3.6/site-packages/flask/_compat.py", line 35, in reraise
    raise value
  File "/home/aryton/Kode/counter_point/venv/lib/python3.6/site-packages/flask/app.py", line 1813, in full_dispatch_request
    rv = self.dispatch_request()
  File "/home/aryton/Kode/counter_point/venv/lib/python3.6/site-packages/flask/app.py", line 1799, in dispatch_request
    return self.view_functions[rule.endpoint](**req.view_args)
  File "/home/aryton/Kode/counter_point/app/views.py", line 39, in get_results
    input_article = create_article(article_url)
UnboundLocalError: local variable 'create_article' referenced before assignment
Exception on /views/results [POST]
Traceback (most recent call last):
  File "/home/aryton/Kode/counter_point/venv/lib/python3.6/site-packages/flask/app.py", line 2292, in wsgi_app
    response = self.full_dispatch_request()
  File "/home/aryton/Kode/counter_point/venv/lib/python3.6/site-packages/flask/app.py", line 1815, in full_dispatch_request
    rv = self.handle_user_exception(e)
  File "/home/aryton/Kode/counter_point/venv/lib/python3.6/site-packages/flask_restplus/api.py", line 583, in error_router
    return original_handler(e)
  File "/home/aryton/Kode/counter_point/venv/lib/python3.6/site-packages/flask/app.py", line 1718, in handle_user_exception
    reraise(exc_type, exc_value, tb)
  File "/home/aryton/Kode/counter_point/venv/lib/python3.6/site-packages/flask/_compat.py", line 35, in reraise
    raise value
  File "/home/aryton/Kode/counter_point/venv/lib/python3.6/site-packages/flask/app.py", line 1813, in full_dispatch_request
    rv = self.dispatch_request()
  File "/home/aryton/Kode/counter_point/venv/lib/python3.6/site-packages/flask/app.py", line 1799, in dispatch_request
    return self.view_functions[rule.endpoint](**req.view_args)
  File "/home/aryton/Kode/counter_point/app/views.py", line 39, in get_results
    input_article = create_article(article_url)
UnboundLocalError: local variable 'create_article' referenced before assignment
Exception on /views/results [POST]
Traceback (most recent call last):
  File "/home/aryton/Kode/counter_point/venv/lib/python3.6/site-packages/flask/app.py", line 2292, in wsgi_app
    response = self.full_dispatch_request()
  File "/home/aryton/Kode/counter_point/venv/lib/python3.6/site-packages/flask/app.py", line 1815, in full_dispatch_request
    rv = self.handle_user_exception(e)
  File "/home/aryton/Kode/counter_point/venv/lib/python3.6/site-packages/flask_restplus/api.py", line 583, in error_router
    return original_handler(e)
  File "/home/aryton/Kode/counter_point/venv/lib/python3.6/site-packages/flask/app.py", line 1718, in handle_user_exception
    reraise(exc_type, exc_value, tb)
  File "/home/aryton/Kode/counter_point/venv/lib/python3.6/site-packages/flask/_compat.py", line 35, in reraise
    raise value
  File "/home/aryton/Kode/counter_point/venv/lib/python3.6/site-packages/flask/app.py", line 1813, in full_dispatch_request
    rv = self.dispatch_request()
  File "/home/aryton/Kode/counter_point/venv/lib/python3.6/site-packages/flask/app.py", line 1799, in dispatch_request
    return self.view_functions[rule.endpoint](**req.view_args)
  File "/home/aryton/Kode/counter_point/app/views.py", line 39, in get_results
    input_article = create_article(article_url)
UnboundLocalError: local variable 'create_article' referenced before assignment
Exception on /views/results [POST]
Traceback (most recent call last):
  File "/home/aryton/Kode/counter_point/venv/lib/python3.6/site-packages/flask/app.py", line 2292, in wsgi_app
    response = self.full_dispatch_request()
  File "/home/aryton/Kode/counter_point/venv/lib/python3.6/site-packages/flask/app.py", line 1815, in full_dispatch_request
    rv = self.handle_user_exception(e)
  File "/home/aryton/Kode/counter_point/venv/lib/python3.6/site-packages/flask_restplus/api.py", line 583, in error_router
    return original_handler(e)
  File "/home/aryton/Kode/counter_point/venv/lib/python3.6/site-packages/flask/app.py", line 1718, in handle_user_exception
    reraise(exc_type, exc_value, tb)
  File "/home/aryton/Kode/counter_point/venv/lib/python3.6/site-packages/flask/_compat.py", line 35, in reraise
    raise value
  File "/home/aryton/Kode/counter_point/venv/lib/python3.6/site-packages/flask/app.py", line 1813, in full_dispatch_request
    rv = self.dispatch_request()
  File "/home/aryton/Kode/counter_point/venv/lib/python3.6/site-packages/flask/app.py", line 1799, in dispatch_request
    return self.view_functions[rule.endpoint](**req.view_args)
  File "/home/aryton/Kode/counter_point/app/views.py", line 48, in get_results
    input_article = create_article(article_url)
  File "/home/aryton/Kode/counter_point/app/views.py", line 31, in create_article
    article_text = text_from_html(requests.get(article).content)
NameError: name 'article' is not defined
Exception on /views/results [POST]
Traceback (most recent call last):
  File "/home/aryton/Kode/counter_point/venv/lib/python3.6/site-packages/flask/app.py", line 2292, in wsgi_app
    response = self.full_dispatch_request()
  File "/home/aryton/Kode/counter_point/venv/lib/python3.6/site-packages/flask/app.py", line 1815, in full_dispatch_request
    rv = self.handle_user_exception(e)
  File "/home/aryton/Kode/counter_point/venv/lib/python3.6/site-packages/flask_restplus/api.py", line 583, in error_router
    return original_handler(e)
  File "/home/aryton/Kode/counter_point/venv/lib/python3.6/site-packages/flask/app.py", line 1718, in handle_user_exception
    reraise(exc_type, exc_value, tb)
  File "/home/aryton/Kode/counter_point/venv/lib/python3.6/site-packages/flask/_compat.py", line 35, in reraise
    raise value
  File "/home/aryton/Kode/counter_point/venv/lib/python3.6/site-packages/flask/app.py", line 1813, in full_dispatch_request
    rv = self.dispatch_request()
  File "/home/aryton/Kode/counter_point/venv/lib/python3.6/site-packages/flask/app.py", line 1799, in dispatch_request
    return self.view_functions[rule.endpoint](**req.view_args)
  File "/home/aryton/Kode/counter_point/app/views.py", line 90, in get_results
    neutral_articles.append(create_article(neutral_url))
AttributeError: 'str' object has no attribute 'append'
Exception on /views/results [POST]
Traceback (most recent call last):
  File "/home/aryton/Kode/counter_point/venv/lib/python3.6/site-packages/flask/app.py", line 2292, in wsgi_app
    response = self.full_dispatch_request()
  File "/home/aryton/Kode/counter_point/venv/lib/python3.6/site-packages/flask/app.py", line 1815, in full_dispatch_request
    rv = self.handle_user_exception(e)
  File "/home/aryton/Kode/counter_point/venv/lib/python3.6/site-packages/flask_restplus/api.py", line 583, in error_router
    return original_handler(e)
  File "/home/aryton/Kode/counter_point/venv/lib/python3.6/site-packages/flask/app.py", line 1718, in handle_user_exception
    reraise(exc_type, exc_value, tb)
  File "/home/aryton/Kode/counter_point/venv/lib/python3.6/site-packages/flask/_compat.py", line 35, in reraise
    raise value
  File "/home/aryton/Kode/counter_point/venv/lib/python3.6/site-packages/flask/app.py", line 1813, in full_dispatch_request
    rv = self.dispatch_request()
  File "/home/aryton/Kode/counter_point/venv/lib/python3.6/site-packages/flask/app.py", line 1799, in dispatch_request
    return self.view_functions[rule.endpoint](**req.view_args)
  File "/home/aryton/Kode/counter_point/app/views.py", line 98, in get_results
    return render_template('results.html', main_article=input_article, article_trunc=('%.40s' % a.url),
NameError: name 'a' is not defined
Exception on /views/results [POST]
Traceback (most recent call last):
  File "/home/aryton/Kode/counter_point/venv/lib/python3.6/site-packages/flask/app.py", line 2292, in wsgi_app
    response = self.full_dispatch_request()
  File "/home/aryton/Kode/counter_point/venv/lib/python3.6/site-packages/flask/app.py", line 1815, in full_dispatch_request
    rv = self.handle_user_exception(e)
  File "/home/aryton/Kode/counter_point/venv/lib/python3.6/site-packages/flask_restplus/api.py", line 583, in error_router
    return original_handler(e)
  File "/home/aryton/Kode/counter_point/venv/lib/python3.6/site-packages/flask/app.py", line 1718, in handle_user_exception
    reraise(exc_type, exc_value, tb)
  File "/home/aryton/Kode/counter_point/venv/lib/python3.6/site-packages/flask/_compat.py", line 35, in reraise
    raise value
  File "/home/aryton/Kode/counter_point/venv/lib/python3.6/site-packages/flask/app.py", line 1813, in full_dispatch_request
    rv = self.dispatch_request()
  File "/home/aryton/Kode/counter_point/venv/lib/python3.6/site-packages/flask/app.py", line 1799, in dispatch_request
    return self.view_functions[rule.endpoint](**req.view_args)
  File "/home/aryton/Kode/counter_point/app/views.py", line 99, in get_results
    positive_list=positive_list, neutral_list=neutral_list, negative_list=negative_list)
NameError: name 'positive_list' is not defined
